<?xml version='1.0'?>

<robot name="udacity_bot" xmlns:xacro="http://www.ros.org/wiki/xacro">

<xacro:include filename="$(find udacity_bot)/urdf/udacity_bot.gazebo" />

  <link name="robot_footprint"></link>

  <joint name="robot_footprint_joint" type="fixed">
    <origin xyz="0 0 0" rpy="0 0 0" />
    <parent link="robot_footprint"/>
    <child link="chassis" />
  </joint>

  <link name='chassis'>
    <pose>0 0 0.1 0 0 0</pose>

    <inertial>
      <mass value="15.0"/>
      <origin xyz="0.0 0 0" rpy=" 0 0 0"/>
      <inertia
          ixx="0.1" ixy="0" ixz="0"
          iyy="0.1" iyz="0"
          izz="0.1"
      />
    </inertial>

    <collision name='collision'>
      <origin xyz="0 0 0" rpy=" 0 0 0"/>
      <geometry>
        <box size=".6 .4 .1"/>
      </geometry>
    </collision>

    <visual name='chassis_visual'>
      <origin xyz="0 0 0" rpy=" 0 0 0"/>
      <geometry>
        <box size=".6 .4 .1"/>
      </geometry>
    </visual>
  </link>
<!--#########     left front wheel link        ##############################-->
  <link name='left_front_wheel'>
    <collision name='left_front_wheel_collision'>
      <origin xyz="0 0 0" rpy=" 0 0 0"/>
        <geometry>
          <cylinder radius="0.1" length="0.05"/>
        </geometry>
    </collision>

    <inertial>
      <mass value="5.0"/>
      <origin xyz="0 0 0" rpy=" 0 0 0"/>
      <inertia
          ixx="0.1" ixy="0" ixz="0"
          iyy="0.1" iyz="0"
          izz="0.1"
      />
    </inertial>

    <visual name='left_front_wheel_visual'>
      <origin xyz="0 0 0" rpy=" 0 0 0"/>
        <geometry>
          <mesh filename="package://udacity_bot/meshes/omni_wheel.dae"/>
        </geometry>
    </visual>
  </link>

  <!--#########     left rear wheel link       ##############################-->
    <link name='left_rear_wheel'>
      <collision name='left_rear_wheel_collision'>
        <origin xyz="0 0 0" rpy=" 0 0 0"/>
          <geometry>
            <cylinder radius="0.1" length="0.05"/>
          </geometry>
      </collision>

      <inertial>
        <mass value="5.0"/>
        <origin xyz="0 0 0" rpy=" 0 0 0"/>
        <inertia
            ixx="0.1" ixy="0" ixz="0"
            iyy="0.1" iyz="0"
            izz="0.1"
        />
      </inertial>

      <visual name='left_rear_wheel_visual'>
        <origin xyz="0 0 0" rpy=" 0 0 0"/>
          <geometry>
            <mesh filename="package://udacity_bot/meshes/omni_wheel.dae"/>
          </geometry>
      </visual>
    </link>

<!--#########     right front wheel link        #############################-->
  <link name='right_front_wheel'>
    <collision name='right_front_wheel_collision'>
      <origin xyz="0 0 0" rpy=" 0 0 0"/>
        <geometry>
          <cylinder radius="0.1" length="0.05"/>
        </geometry>
    </collision>

    <inertial>
      <mass value="5.0"/>
      <origin xyz="0 0 0" rpy=" 0 0 0"/>
      <inertia
          ixx="0.1" ixy="0" ixz="0"
          iyy="0.1" iyz="0"
          izz="0.1"
      />
    </inertial>

    <visual name='right_front_wheel_visual'>
      <origin xyz="0 0 0" rpy=" 0 0 0"/>
        <geometry>
          <mesh filename="package://udacity_bot/meshes/omni_wheel.dae"/>
        </geometry>
    </visual>
  </link>
<!--#########     right rear wheel link        ##############################-->
  <link name='right_rear_wheel'>
    <collision name='right_rear_wheel_collision'>
      <origin xyz="0 0 0" rpy=" 0 0 0"/>
        <geometry>
          <cylinder radius="0.1" length="0.05"/>
        </geometry>
    </collision>

    <inertial>
      <mass value="5.0"/>
      <origin xyz="0 0 0" rpy=" 0 0 0"/>
      <inertia
          ixx="0.1" ixy="0" ixz="0"
          iyy="0.1" iyz="0"
          izz="0.1"
      />
    </inertial>

    <visual name='right_front_wheel_visual'>
      <origin xyz="0 0 0" rpy=" 0 0 0"/>
        <geometry>
          <mesh filename="package://udacity_bot/meshes/omni_wheel.dae"/>
        </geometry>
    </visual>
  </link>
<!--#########################################################################-->
<!-- wheel hing joints -->
  <joint type="continuous" name="left_front_wheel_hinge">
    <origin xyz="0.2 0.25 0" rpy="0 0 0"/>
    <child link="left_wheel"/>
    <parent link="chassis"/>
    <axis xyz="0 1 0" rpy="0 0 0"/>
    <limit effort="10000" velocity="1000"/>
    <joint_properties damping="1.0" friction="1.0"/>
  </joint>

  <joint type="continuous" name="left_rear_wheel_hinge">
    <origin xyz="-0.2 0.25 0" rpy="0 0 0"/>
    <child link="left_wheel"/>
    <parent link="chassis"/>
    <axis xyz="0 1 0" rpy="0 0 0"/>
    <limit effort="10000" velocity="1000"/>
    <joint_properties damping="1.0" friction="1.0"/>
  </joint>

  <joint type="continuous" name="right_front_wheel_hinge">
      <origin xyz="0.2 -0.25 0" rpy="0 0 0"/>
      <child link="right_wheel"/>
      <parent link="chassis"/>
      <axis xyz="0 1 0" rpy="0 0 0"/>
      <limit effort="10000" velocity="1000"/>
      <joint_properties damping="1.0" friction="1.0"/>
  </joint>

  <joint type="continuous" name="right_rear_wheel_hinge">
      <origin xyz="-0.2 -0.25 0" rpy="0 0 0"/>
      <child link="right_wheel"/>
      <parent link="chassis"/>
      <axis xyz="0 1 0" rpy="0 0 0"/>
      <limit effort="10000" velocity="1000"/>
      <joint_properties damping="1.0" friction="1.0"/>

<!--###################        camera link           ########################-->
  <link name="camera">
      <collision name="camera_collision">
        <origin xyz="0 0 0" rpy=" 0 0 0"/>
          <geometry>
            <box size="0.05 0.05 0.05"/>
          </geometry>
      </collision>

      <inertial>
        <mass value="0.1"/>
        <origin xyz="0 0 0" rpy=" 0 0 0"/>
        <inertia
            ixx="1e-6" ixy="0" ixz="0"
            iyy="1e-6" iyz="0"
            izz="1e-6"
        />
      </inertial>

      <visual name="camera_visual">
        <origin xyz="0 0 0" rpy=" 0 0 0"/>
          <geometry>
            <box size="0.05 0.05 0.05"/>
          </geometry>
      </visual>
  </link>

  <joint name="camera_joint" type="fixed">
    <origin xyz="0.2 0 0" rpy="0 0 0" />
    <parent link="chassis"/>
    <child link="camera" />
  </joint>

<!--###################        laser link            ########################-->
  <link name="hokuyo">
    <collision name="hokuyo_collision">
      <origin xyz="0 0 0" rpy=" 0 0 0"/>
        <geometry>
          <box size="0.1 0.1 0.1"/>
        </geometry>
    </collision>

    <inertial>
      <mass value="0.1"/>
      <origin xyz="0 0 0" rpy=" 0 0 0"/>
      <inertia
          ixx="1e-6" ixy="0" ixz="0"
          iyy="1e-6" iyz="0"
          izz="1e-6"
      />
    </inertial>

    <visual name="hokuyo_visual">
      <origin xyz="0 0 0" rpy=" 0 0 0"/>
        <geometry>
          <mesh filename="package://udacity_bot/meshes/hokuyo.dae"/>
        </geometry>
    </visual>
  </link>

  <joint name="hokuyo_joint" type="fixed">
    <origin xyz="0.15 0 0.1" rpy="0 0 0" />
    <parent link="chassis"/>
    <child link="hokuyo" />
  </joint>

</robot>
